Workbook

Sheet Dashboard
B2: Parameter | C2: Value | D2: Description
B3: x_prime | C3: 0.41 | D3: Target position (peak) | F3: HOW TO USE THIS
B4: x_far | D4: Away position for convergence check | F4: Enter your roll number in cell C3 This act as x' in dirac delta function generator
B5: L | C5: 0.5 | D5: Integral upper limit | F5: This program uses 500 terms but you can extend it easilly to 1000 and beyond by just dragging
B6: n1 | C6: 20 | D6: Low-n approximation | F6: 1. First and second plot is in "Point Convergence " sheet
B7: n2 | C7: 100 | D7: High-n approximation | F7: 2. For the first plot, take column A and column B
B8: k_max | C8: 500 | D8: Terms for convergence sheets (Max 1000 recommended) | F8: 3. For the second plot, take column A and column C
B9: a1 | C9: 0
B10: b1 | C10: =C3-0.01 -> 0.4 | F10: 4. For the third plot use "Spatial DDF" sheet take column A and C for the plot use n1 and n2 for two graphs : for n1 C6 cell and for n2 its C7 cell, currently its n1=20 and n2=100
B11: a2 | C11: =C3-0.01 -> 0.4 | F11: 5. Fot fourth , fifth and sisth plot use sheet Integration and take column A and C for fourth, A and F for fifth and A and I for sixth
B12: b2 | C12: =C3+0.01 -> 0.42
B13: a3 | C13: =C3+0.01 -> 0.42
B14: b3 | C14: 1

Sheet Point Convergence
A1: k | B1: Term (x=x') | C1: CumSum (x=x') | E1: Term (x=x_far) | F1: CumSum (x=x_far) | T1: 1
A2: 1 | B2: =2*SIN(1*PI()*Dashboard!$C$3)*SIN(1*PI()*Dashboard!$C$3) -> 1.8443279 | C2: =SUM($B$2:B2) -> 1.8443279 | E2: =2*SIN(1*PI()*Dashboard!$C$3)*SIN(1*PI()*Dashboard!$C$4) -> 0 | F2: =SUM($E$2:E2) -> 0 | T2: 2
A3: 2 | B3: =2*SIN(2*PI()*Dashboard!$C$3)*SIN(2*PI()*Dashboard!$C$3) -> 0.57422071 | C3: =SUM($B$2:B3) -> 2.4185486 | E3: =2*SIN(2*PI()*Dashboard!$C$3)*SIN(2*PI()*Dashboard!$C$4) -> 0 | F3: =SUM($E$2:E3) -> 0
A4: 3 | B4: =2*SIN(3*PI()*Dashboard!$C$3)*SIN(3*PI()*Dashboard!$C$3) -> 0.87466677 | C4: =SUM($B$2:B4) -> 3.2932154 | E4: =2*SIN(3*PI()*Dashboard!$C$3)*SIN(3*PI()*Dashboard!$C$4) -> 0 | F4: =SUM($E$2:E4) -> 0
A5: 4 | B5: =2*SIN(4*PI()*Dashboard!$C$3)*SIN(4*PI()*Dashboard!$C$3) -> 1.637424 | C5: =SUM($B$2:B5) -> 4.9306394 | E5: =2*SIN(4*PI()*Dashboard!$C$3)*SIN(4*PI()*Dashboard!$C$4) -> 0 | F5: =SUM($E$2:E5) -> 0
A6: 5 | B6: =2*SIN(5*PI()*Dashboard!$C$3)*SIN(5*PI()*Dashboard!$C$3) -> 0.048943484 | C6: =SUM($B$2:B6) -> 4.9795829 | E6: =2*SIN(5*PI()*Dashboard!$C$3)*SIN(5*PI()*Dashboard!$C$4) -> 0 | F6: =SUM($E$2:E6) -> 0
A7: 6 | B7: =2*SIN(6*PI()*Dashboard!$C$3)*SIN(6*PI()*Dashboard!$C$3) -> 1.9685832 | C7: =SUM($B$2:B7) -> 6.948166 | E7: =2*SIN(6*PI()*Dashboard!$C$3)*SIN(6*PI()*Dashboard!$C$4) -> 0 | F7: =SUM($E$2:E7) -> 0
A8: 7 | B8: =2*SIN(7*PI()*Dashboard!$C$3)*SIN(7*PI()*Dashboard!$C$3) -> 0.31545289 | C8: =SUM($B$2:B8) -> 7.2636189 | E8: =2*SIN(7*PI()*Dashboard!$C$3)*SIN(7*PI()*Dashboard!$C$4) -> 0 | F8: =SUM($E$2:E8) -> 0
A9: 8 | B9: =2*SIN(8*PI()*Dashboard!$C$3)*SIN(8*PI()*Dashboard!$C$3) -> 1.1873813 | C9: =SUM($B$2:B9) -> 8.4510002 | E9: =2*SIN(8*PI()*Dashboard!$C$3)*SIN(8*PI()*Dashboard!$C$4) -> 0 | F9: =SUM($E$2:E9) -> 0
A10: 9 | B10: =2*SIN(9*PI()*Dashboard!$C$3)*SIN(9*PI()*Dashboard!$C$3) -> 1.3681246 | C10: =SUM($B$2:B10) -> 9.8191248 | E10: =2*SIN(9*PI()*Dashboard!$C$3)*SIN(9*PI()*Dashboard!$C$4) -> 0 | F10: =SUM($E$2:E10) -> 0
A11: 10 | B11: =2*SIN(10*PI()*Dashboard!$C$3)*SIN(10*PI()*Dashboard!$C$3) -> 0.19098301 | C11: =SUM($B$2:B11) -> 10.010108 | E11: =2*SIN(10*PI()*Dashboard!$C$3)*SIN(10*PI()*Dashboard!$C$4) -> 0 | F11: =SUM($E$2:E11) -> 0
A12: 11 | B12: =2*SIN(11*PI()*Dashboard!$C$3)*SIN(11*PI()*Dashboard!$C$3) -> 1.9980267 | C12: =SUM($B$2:B12) -> 12.008135 | E12: =2*SIN(11*PI()*Dashboard!$C$3)*SIN(11*PI()*Dashboard!$C$4) -> 0 | F12: =SUM($E$2:E12) -> 0
A13: 12 | B13: =2*SIN(12*PI()*Dashboard!$C$3)*SIN(12*PI()*Dashboard!$C$3) -> 0.12369332 | C13: =SUM($B$2:B13) -> 12.131828 | E13: =2*SIN(12*PI()*Dashboard!$C$3)*SIN(12*PI()*Dashboard!$C$4) -> 0 | F13: =SUM($E$2:E13) -> 0
A14: 13 | B14: =2*SIN(13*PI()*Dashboard!$C$3)*SIN(13*PI()*Dashboard!$C$3) -> 1.4817537 | C14: =SUM($B$2:B14) -> 13.613582 | E14: =2*SIN(13*PI()*Dashboard!$C$3)*SIN(13*PI()*Dashboard!$C$4) -> 0 | F14: =SUM($E$2:E14) -> 0
A15: 14 | B15: =2*SIN(14*PI()*Dashboard!$C$3)*SIN(14*PI()*Dashboard!$C$3) -> 1.0627905 | C15: =SUM($B$2:B15) -> 14.676372 | E15: =2*SIN(14*PI()*Dashboard!$C$3)*SIN(14*PI()*Dashboard!$C$4) -> 0 | F15: =SUM($E$2:E15) -> 0
A16: 15 | B16: =2*SIN(15*PI()*Dashboard!$C$3)*SIN(15*PI()*Dashboard!$C$3) -> 0.41221475 | C16: =SUM($B$2:B16) -> 15.088587 | E16: =2*SIN(15*PI()*Dashboard!$C$3)*SIN(15*PI()*Dashboard!$C$4) -> 0 | F16: =SUM($E$2:E16) -> 0
A17: 16 | B17: =2*SIN(16*PI()*Dashboard!$C$3)*SIN(16*PI()*Dashboard!$C$3) -> 1.9297765 | C17: =SUM($B$2:B17) -> 17.018363 | E17: =2*SIN(16*PI()*Dashboard!$C$3)*SIN(16*PI()*Dashboard!$C$4) -> 0 | F17: =SUM($E$2:E17) -> 0
A18: 17 | B18: =2*SIN(17*PI()*Dashboard!$C$3)*SIN(17*PI()*Dashboard!$C$3) -> 0.017712749 | C18: =SUM($B$2:B18) -> 17.036076 | E18: =2*SIN(17*PI()*Dashboard!$C$3)*SIN(17*PI()*Dashboard!$C$4) -> 0 | F18: =SUM($E$2:E18) -> 0
A19: 18 | B19: =2*SIN(18*PI()*Dashboard!$C$3)*SIN(18*PI()*Dashboard!$C$3) -> 1.7289686 | C19: =SUM($B$2:B19) -> 18.765045 | E19: =2*SIN(18*PI()*Dashboard!$C$3)*SIN(18*PI()*Dashboard!$C$4) -> 0 | F19: =SUM($E$2:E19) -> 0
A20: 19 | B20: =2*SIN(19*PI()*Dashboard!$C$3)*SIN(19*PI()*Dashboard!$C$3) -> 0.75131011 | C20: =SUM($B$2:B20) -> 19.516355 | E20: =2*SIN(19*PI()*Dashboard!$C$3)*SIN(19*PI()*Dashboard!$C$4) -> 0 | F20: =SUM($E$2:E20) -> 0
A21: 20 | B21: =2*SIN(20*PI()*Dashboard!$C$3)*SIN(20*PI()*Dashboard!$C$3) -> 0.69098301 | C21: =SUM($B$2:B21) -> 20.207338 | E21: =2*SIN(20*PI()*Dashboard!$C$3)*SIN(20*PI()*Dashboard!$C$4) -> 0 | F21: =SUM($E$2:E21) -> 0
A22: 21 | B22: =2*SIN(21*PI()*Dashboard!$C$3)*SIN(21*PI()*Dashboard!$C$3) -> 1.7705132 | C22: =SUM($B$2:B22) -> 21.977851 | E22: =2*SIN(21*PI()*Dashboard!$C$3)*SIN(21*PI()*Dashboard!$C$4) -> 0 | F22: =SUM($E$2:E22) -> 0
A23: 22 | B23: =2*SIN(22*PI()*Dashboard!$C$3)*SIN(22*PI()*Dashboard!$C$3) -> 0.0078852987 | C23: =SUM($B$2:B23) -> 21.985736 | E23: =2*SIN(22*PI()*Dashboard!$C$3)*SIN(22*PI()*Dashboard!$C$4) -> 0 | F23: =SUM($E$2:E23) -> 0
A24: 23 | B24: =2*SIN(23*PI()*Dashboard!$C$3)*SIN(23*PI()*Dashboard!$C$3) -> 1.9048271 | C24: =SUM($B$2:B24) -> 23.890563 | E24: =2*SIN(23*PI()*Dashboard!$C$3)*SIN(23*PI()*Dashboard!$C$4) -> 0 | F24: =SUM($E$2:E24) -> 0
A25: 24 | B25: =2*SIN(24*PI()*Dashboard!$C$3)*SIN(24*PI()*Dashboard!$C$3) -> 0.46417321 | C25: =SUM($B$2:B25) -> 24.354737 | E25: =2*SIN(24*PI()*Dashboard!$C$3)*SIN(24*PI()*Dashboard!$C$4) -> 0 | F25: =SUM($E$2:E25) -> 0
A26: 25 | B26: =2*SIN(25*PI()*Dashboard!$C$3)*SIN(25*PI()*Dashboard!$C$3) -> 1 | C26: =SUM($B$2:B26) -> 25.354737 | E26: =2*SIN(25*PI()*Dashboard!$C$3)*SIN(25*PI()*Dashboard!$C$4) -> 0 | F26: =SUM($E$2:E26) -> 0
A27: 26 | B27: =2*SIN(26*PI()*Dashboard!$C$3)*SIN(26*PI()*Dashboard!$C$3) -> 1.5358268 | C27: =SUM($B$2:B27) -> 26.890563 | E27: =2*SIN(26*PI()*Dashboard!$C$3)*SIN(26*PI()*Dashboard!$C$4) -> 0 | F27: =SUM($E$2:E27) -> 0
A28: 27 | B28: =2*SIN(27*PI()*Dashboard!$C$3)*SIN(27*PI()*Dashboard!$C$3) -> 0.095172948 | C28: =SUM($B$2:B28) -> 26.985736 | E28: =2*SIN(27*PI()*Dashboard!$C$3)*SIN(27*PI()*Dashboard!$C$4) -> 0 | F28: =SUM($E$2:E28) -> 0
A29: 28 | B29: =2*SIN(28*PI()*Dashboard!$C$3)*SIN(28*PI()*Dashboard!$C$3) -> 1.9921147 | C29: =SUM($B$2:B29) -> 28.977851 | E29: =2*SIN(28*PI()*Dashboard!$C$3)*SIN(28*PI()*Dashboard!$C$4) -> 0 | F29: =SUM($E$2:E29) -> 0
A30: 29 | B30: =2*SIN(29*PI()*Dashboard!$C$3)*SIN(29*PI()*Dashboard!$C$3) -> 0.22948676 | C30: =SUM($B$2:B30) -> 29.207338 | E30: =2*SIN(29*PI()*Dashboard!$C$3)*SIN(29*PI()*Dashboard!$C$4) -> 0 | F30: =SUM($E$2:E30) -> 0
A31: 30 | B31: =2*SIN(30*PI()*Dashboard!$C$3)*SIN(30*PI()*Dashboard!$C$3) -> 1.309017 | C31: =SUM($B$2:B31) -> 30.516355 | E31: =2*SIN(30*PI()*Dashboard!$C$3)*SIN(30*PI()*Dashboard!$C$4) -> 0 | F31: =SUM($E$2:E31) -> 0
A32: 31 | B32: =2*SIN(31*PI()*Dashboard!$C$3)*SIN(31*PI()*Dashboard!$C$3) -> 1.2486899 | C32: =SUM($B$2:B32) -> 31.765045 | E32: =2*SIN(31*PI()*Dashboard!$C$3)*SIN(31*PI()*Dashboard!$C$4) -> 0 | F32: =SUM($E$2:E32) -> 0
A33: 32 | B33: =2*SIN(32*PI()*Dashboard!$C$3)*SIN(32*PI()*Dashboard!$C$3) -> 0.27103137 | C33: =SUM($B$2:B33) -> 32.036076 | E33: =2*SIN(32*PI()*Dashboard!$C$3)*SIN(32*PI()*Dashboard!$C$4) -> 0 | F33: =SUM($E$2:E33) -> 0
A34: 33 | B34: =2*SIN(33*PI()*Dashboard!$C$3)*SIN(33*PI()*Dashboard!$C$3) -> 1.9822873 | C34: =SUM($B$2:B34) -> 34.018363 | E34: =2*SIN(33*PI()*Dashboard!$C$3)*SIN(33*PI()*Dashboard!$C$4) -> 0 | F34: =SUM($E$2:E34) -> 0
A35: 34 | B35: =2*SIN(34*PI()*Dashboard!$C$3)*SIN(34*PI()*Dashboard!$C$3) -> 0.070223514 | C35: =SUM($B$2:B35) -> 34.088587 | E35: =2*SIN(34*PI()*Dashboard!$C$3)*SIN(34*PI()*Dashboard!$C$4) -> 0 | F35: =SUM($E$2:E35) -> 0
A36: 35 | B36: =2*SIN(35*PI()*Dashboard!$C$3)*SIN(35*PI()*Dashboard!$C$3) -> 1.5877853 | C36: =SUM($B$2:B36) -> 35.676372 | E36: =2*SIN(35*PI()*Dashboard!$C$3)*SIN(35*PI()*Dashboard!$C$4) -> 0 | F36: =SUM($E$2:E36) -> 0
A37: 36 | B37: =2*SIN(36*PI()*Dashboard!$C$3)*SIN(36*PI()*Dashboard!$C$3) -> 0.93720948 | C37: =SUM($B$2:B37) -> 36.613582 | E37: =2*SIN(36*PI()*Dashboard!$C$3)*SIN(36*PI()*Dashboard!$C$4) -> 0 | F37: =SUM($E$2:E37) -> 0
A38: 37 | B38: =2*SIN(37*PI()*Dashboard!$C$3)*SIN(37*PI()*Dashboard!$C$3) -> 0.51824633 | C38: =SUM($B$2:B38) -> 37.131828 | E38: =2*SIN(37*PI()*Dashboard!$C$3)*SIN(37*PI()*Dashboard!$C$4) -> 0 | F38: =SUM($E$2:E38) -> 0
A39: 38 | B39: =2*SIN(38*PI()*Dashboard!$C$3)*SIN(38*PI()*Dashboard!$C$3) -> 1.8763067 | C39: =SUM($B$2:B39) -> 39.008135 | E39: =2*SIN(38*PI()*Dashboard!$C$3)*SIN(38*PI()*Dashboard!$C$4) -> 0 | F39: =SUM($E$2:E39) -> 0
A40: 39 | B40: =2*SIN(39*PI()*Dashboard!$C$3)*SIN(39*PI()*Dashboard!$C$3) -> 0.0019732716 | C40: =SUM($B$2:B40) -> 39.010108 | E40: =2*SIN(39*PI()*Dashboard!$C$3)*SIN(39*PI()*Dashboard!$C$4) -> 0 | F40: =SUM($E$2:E40) -> 0
...

Sheet Spatial DDF
A1: x | B1: delta_n1 | C1: delta_n2
A2: 0 | B2: =2*SUMPRODUCT(SIN(ROW(INDIRECT("1:"&Dashboard!$C$6))*PI()*Dashboard!$C$3), SIN(ROW(INDIRECT("1:"&Dashboard!$C$6))*PI()*A2)) -> 0 | C2: =2*SUMPRODUCT(SIN(ROW(INDIRECT("1:"&Dashboard!$C$7))*PI()*Dashboard!$C$3), SIN(ROW(INDIRECT("1:"&Dashboard!$C$7))*PI()*A2)) -> 0
A3: 0.01 | B3: =2*SUMPRODUCT(SIN(ROW(INDIRECT("1:"&Dashboard!$C$6))*PI()*Dashboard!$C$3), SIN(ROW(INDIRECT("1:"&Dashboard!$C$6))*PI()*A3)) -> -0.26755583 | C3: =2*SUMPRODUCT(SIN(ROW(INDIRECT("1:"&Dashboard!$C$7))*PI()*Dashboard!$C$3), SIN(ROW(INDIRECT("1:"&Dashboard!$C$7))*PI()*A3)) -> -3.9405978e-14
A4: 0.02 | B4: =2*SUMPRODUCT(SIN(ROW(INDIRECT("1:"&Dashboard!$C$6))*PI()*Dashboard!$C$3), SIN(ROW(INDIRECT("1:"&Dashboard!$C$6))*PI()*A4)) -> -0.45270621 | C4: =2*SUMPRODUCT(SIN(ROW(INDIRECT("1:"&Dashboard!$C$7))*PI()*Dashboard!$C$3), SIN(ROW(INDIRECT("1:"&Dashboard!$C$7))*PI()*A4)) -> 8.5764729e-14
A5: 0.03 | B5: =2*SUMPRODUCT(SIN(ROW(INDIRECT("1:"&Dashboard!$C$6))*PI()*Dashboard!$C$3), SIN(ROW(INDIRECT("1:"&Dashboard!$C$6))*PI()*A5)) -> -0.49595675 | C5: =2*SUMPRODUCT(SIN(ROW(INDIRECT("1:"&Dashboard!$C$7))*PI()*Dashboard!$C$3), SIN(ROW(INDIRECT("1:"&Dashboard!$C$7))*PI()*A5)) -> -5.0542903e-14
A6: 0.04 | B6: =2*SUMPRODUCT(SIN(ROW(INDIRECT("1:"&Dashboard!$C$6))*PI()*Dashboard!$C$3), SIN(ROW(INDIRECT("1:"&Dashboard!$C$6))*PI()*A6)) -> -0.37843108 | C6: =2*SUMPRODUCT(SIN(ROW(INDIRECT("1:"&Dashboard!$C$7))*PI()*Dashboard!$C$3), SIN(ROW(INDIRECT("1:"&Dashboard!$C$7))*PI()*A6)) -> 7.4329431e-14
A7: 0.05 | B7: =2*SUMPRODUCT(SIN(ROW(INDIRECT("1:"&Dashboard!$C$6))*PI()*Dashboard!$C$3), SIN(ROW(INDIRECT("1:"&Dashboard!$C$6))*PI()*A7)) -> -0.12974493 | C7: =2*SUMPRODUCT(SIN(ROW(INDIRECT("1:"&Dashboard!$C$7))*PI()*Dashboard!$C$3), SIN(ROW(INDIRECT("1:"&Dashboard!$C$7))*PI()*A7)) -> -1.1834977e-13
A8: 0.06 | B8: =2*SUMPRODUCT(SIN(ROW(INDIRECT("1:"&Dashboard!$C$6))*PI()*Dashboard!$C$3), SIN(ROW(INDIRECT("1:"&Dashboard!$C$6))*PI()*A8)) -> 0.17710723 | C8: =2*SUMPRODUCT(SIN(ROW(INDIRECT("1:"&Dashboard!$C$7))*PI()*Dashboard!$C$3), SIN(ROW(INDIRECT("1:"&Dashboard!$C$7))*PI()*A8)) -> 4.2632564e-14
A9: 0.07 | B9: =2*SUMPRODUCT(SIN(ROW(INDIRECT("1:"&Dashboard!$C$6))*PI()*Dashboard!$C$3), SIN(ROW(INDIRECT("1:"&Dashboard!$C$6))*PI()*A9)) -> 0.44431446 | C9: =2*SUMPRODUCT(SIN(ROW(INDIRECT("1:"&Dashboard!$C$7))*PI()*Dashboard!$C$3), SIN(ROW(INDIRECT("1:"&Dashboard!$C$7))*PI()*A9)) -> -4.1688875e-14
A10: 0.08 | B10: =2*SUMPRODUCT(SIN(ROW(INDIRECT("1:"&Dashboard!$C$6))*PI()*Dashboard!$C$3), SIN(ROW(INDIRECT("1:"&Dashboard!$C$6))*PI()*A10)) -> 0.57794646 | C10: =2*SUMPRODUCT(SIN(ROW(INDIRECT("1:"&Dashboard!$C$7))*PI()*Dashboard!$C$3), SIN(ROW(INDIRECT("1:"&Dashboard!$C$7))*PI()*A10)) -> 8.4210416e-14
A11: 0.09 | B11: =2*SUMPRODUCT(SIN(ROW(INDIRECT("1:"&Dashboard!$C$6))*PI()*Dashboard!$C$3), SIN(ROW(INDIRECT("1:"&Dashboard!$C$6))*PI()*A11)) -> 0.51949119 | C11: =2*SUMPRODUCT(SIN(ROW(INDIRECT("1:"&Dashboard!$C$7))*PI()*Dashboard!$C$3), SIN(ROW(INDIRECT("1:"&Dashboard!$C$7))*PI()*A11)) -> -3.1197267e-14
A12: 0.1 | B12: =2*SUMPRODUCT(SIN(ROW(INDIRECT("1:"&Dashboard!$C$6))*PI()*Dashboard!$C$3), SIN(ROW(INDIRECT("1:"&Dashboard!$C$6))*PI()*A12)) -> 0.27026481 | C12: =2*SUMPRODUCT(SIN(ROW(INDIRECT("1:"&Dashboard!$C$7))*PI()*Dashboard!$C$3), SIN(ROW(INDIRECT("1:"&Dashboard!$C$7))*PI()*A12)) -> 4.196643e-14
A13: 0.11 | B13: =2*SUMPRODUCT(SIN(ROW(INDIRECT("1:"&Dashboard!$C$6))*PI()*Dashboard!$C$3), SIN(ROW(INDIRECT("1:"&Dashboard!$C$6))*PI()*A13)) -> -0.10105925 | C13: =2*SUMPRODUCT(SIN(ROW(INDIRECT("1:"&Dashboard!$C$7))*PI()*Dashboard!$C$3), SIN(ROW(INDIRECT("1:"&Dashboard!$C$7))*PI()*A13)) -> -1.5543122e-14
... A102: 1 | B102: =2*SUMPRODUCT(SIN(ROW(INDIRECT("1:"&Dashboard!$C$6))*PI()*Dashboard!$C$3), SIN(ROW(INDIRECT("1:"&Dashboard!$C$6))*PI()*A102)) -> 8.4350821e-15 | C102: =2*SUMPRODUCT(SIN(ROW(INDIRECT("1:"&Dashboard!$C$7))*PI()*Dashboard!$C$3), SIN(ROW(INDIRECT("1:"&Dashboard!$C$7))*PI()*A102)) -> -4.2158005e-14

Sheet Integration
A1: k | B1: Term (xp < L) | C1: CumSum 1 | E1: Term (xp > L) | F1: CumSum 2 | H1: Term (xp = L) | I1: CumSum 3
A2: 1 | B2: =2*SIN(A2*PI()*Dashboard!$C$3)*(COS(A2*PI()*Dashboard!$C$9)-COS(A2*PI()*Dashboard!$C$10))/(A2*PI()) -> 0.4224269 | C2: =SUM($B$2:B2) -> 0.4224269 | E2: =2*SIN(A2*PI()*Dashboard!$C$3)*(COS(A2*PI()*Dashboard!$C$11)-COS(A2*PI()*Dashboard!$C$12))/(A2*PI()) -> 0.036880491 | F2: =SUM($E$2:E2) -> 0.036880491 | H2: =2*SIN(A2*PI()*Dashboard!$C$3)*(COS(A2*PI()*Dashboard!$C$13)-COS(A2*PI()*Dashboard!$C$14))/(A2*PI()) -> 0.76337651 | I2: =SUM($H$2:H2) -> 0.76337651
A3: 2 | B3: =2*SIN(A3*PI()*Dashboard!$C$3)*(COS(A3*PI()*Dashboard!$C$9)-COS(A3*PI()*Dashboard!$C$10))/(A3*PI()) -> 0.30854407 | C3: =SUM($B$2:B3) -> 0.73097096 | E3: =2*SIN(A3*PI()*Dashboard!$C$3)*(COS(A3*PI()*Dashboard!$C$11)-COS(A3*PI()*Dashboard!$C$12))/(A3*PI()) -> 0.011476859 | F3: =SUM($E$2:E3) -> 0.04835735 | H3: =2*SIN(A3*PI()*Dashboard!$C$3)*(COS(A3*PI()*Dashboard!$C$13)-COS(A3*PI()*Dashboard!$C$14))/(A3*PI()) -> -0.32002093 | I3: =SUM($H$2:H3) -> 0.44335558
A4: 3 | B4: =2*SIN(A4*PI()*Dashboard!$C$3)*(COS(A4*PI()*Dashboard!$C$9)-COS(A4*PI()*Dashboard!$C$10))/(A4*PI()) -> -0.25386792 | C4: =SUM($B$2:B4) -> 0.47710304 | E4: =2*SIN(A4*PI()*Dashboard!$C$3)*(COS(A4*PI()*Dashboard!$C$11)-COS(A4*PI()*Dashboard!$C$12))/(A4*PI()) -> 0.017467449 | F4: =SUM($E$2:E4) -> 0.065824799 | H4: =2*SIN(A4*PI()*Dashboard!$C$3)*(COS(A4*PI()*Dashboard!$C$13)-COS(A4*PI()*Dashboard!$C$14))/(A4*PI()) -> -0.044268999 | I4: =SUM($H$2:H4) -> 0.39908658
A5: 4 | B5: =2*SIN(A5*PI()*Dashboard!$C$3)*(COS(A5*PI()*Dashboard!$C$9)-COS(A5*PI()*Dashboard!$C$10))/(A5*PI()) -> -0.099506872 | C5: =SUM($B$2:B5) -> 0.37759617 | E5: =2*SIN(A5*PI()*Dashboard!$C$3)*(COS(A5*PI()*Dashboard!$C$11)-COS(A5*PI()*Dashboard!$C$12))/(A5*PI()) -> 0.032662357 | F5: =SUM($E$2:E5) -> 0.098487157 | H5: =2*SIN(A5*PI()*Dashboard!$C$3)*(COS(A5*PI()*Dashboard!$C$13)-COS(A5*PI()*Dashboard!$C$14))/(A5*PI()) -> 0.066844515 | I5: =SUM($H$2:H5) -> 0.4659311
A6: 5 | B6: =2*SIN(A6*PI()*Dashboard!$C$3)*(COS(A6*PI()*Dashboard!$C$9)-COS(A6*PI()*Dashboard!$C$10))/(A6*PI()) -> 0 | C6: =SUM($B$2:B6) -> 0.37759617 | E6: =2*SIN(A6*PI()*Dashboard!$C$3)*(COS(A6*PI()*Dashboard!$C$11)-COS(A6*PI()*Dashboard!$C$12))/(A6*PI()) -> 0.0009748492 | F6: =SUM($E$2:E6) -> 0.099462006 | H6: =2*SIN(A6*PI()*Dashboard!$C$3)*(COS(A6*PI()*Dashboard!$C$13)-COS(A6*PI()*Dashboard!$C$14))/(A6*PI()) -> 0.03886086 | I6: =SUM($H$2:H6) -> 0.50479196
A7: 6 | B7: =2*SIN(A7*PI()*Dashboard!$C$3)*(COS(A7*PI()*Dashboard!$C$9)-COS(A7*PI()*Dashboard!$C$10))/(A7*PI()) -> 0.072737459 | C7: =SUM($B$2:B7) -> 0.45033363 | E7: =2*SIN(A7*PI()*Dashboard!$C$3)*(COS(A7*PI()*Dashboard!$C$11)-COS(A7*PI()*Dashboard!$C$12))/(A7*PI()) -> 0.039138927 | F7: =SUM($E$2:E7) -> 0.13860093 | H7: =2*SIN(A7*PI()*Dashboard!$C$3)*(COS(A7*PI()*Dashboard!$C$13)-COS(A7*PI()*Dashboard!$C$14))/(A7*PI()) -> -0.11187639 | I7: =SUM($H$2:H7) -> 0.39291557
A8: 7 | B8: =2*SIN(A8*PI()*Dashboard!$C$3)*(COS(A8*PI()*Dashboard!$C$9)-COS(A8*PI()*Dashboard!$C$10))/(A8*PI()) -> 0.065339678 | C8: =SUM($B$2:B8) -> 0.51567331 | E8: =2*SIN(A8*PI()*Dashboard!$C$3)*(COS(A8*PI()*Dashboard!$C$11)-COS(A8*PI()*Dashboard!$C$12))/(A8*PI()) -> 0.0062583286 | F8: =SUM($E$2:E8) -> 0.14485926 | H8: =2*SIN(A8*PI()*Dashboard!$C$3)*(COS(A8*PI()*Dashboard!$C$13)-COS(A8*PI()*Dashboard!$C$14))/(A8*PI()) -> 0.00063976477 | I8: =SUM($H$2:H8) -> 0.39355533
A9: 8 | B9: =2*SIN(A9*PI()*Dashboard!$C$3)*(COS(A9*PI()*Dashboard!$C$9)-COS(A9*PI()*Dashboard!$C$10))/(A9*PI()) -> -0.11092077 | C9: =SUM($B$2:B9) -> 0.40475253 | E9: =2*SIN(A9*PI()*Dashboard!$C$3)*(COS(A9*PI()*Dashboard!$C$11)-COS(A9*PI()*Dashboard!$C$12))/(A9*PI()) -> 0.02349841 | F9: =SUM($E$2:E9) -> 0.16835767 | H9: =2*SIN(A9*PI()*Dashboard!$C$3)*(COS(A9*PI()*Dashboard!$C$13)-COS(A9*PI()*Dashboard!$C$14))/(A9*PI()) -> 0.087422364 | I9: =SUM($H$2:H9) -> 0.4809777
A10: 9 | B10: =2*SIN(A10*PI()*Dashboard!$C$3)*(COS(A10*PI()*Dashboard!$C$9)-COS(A10*PI()*Dashboard!$C$10))/(A10*PI()) -> -0.040425258 | C10: =SUM($B$2:B10) -> 0.36432727 | E10: =2*SIN(A10*PI()*Dashboard!$C$3)*(COS(A10*PI()*Dashboard!$C$11)-COS(A10*PI()*Dashboard!$C$12))/(A10*PI()) -> 0.026999369 | F10: =SUM($E$2:E10) -> 0.19535704 | H10: =2*SIN(A10*PI()*Dashboard!$C$3)*(COS(A10*PI()*Dashboard!$C$13)-COS(A10*PI()*Dashboard!$C$14))/(A10*PI()) -> -0.10358208 | I10: =SUM($H$2:H10) -> 0.37739562
A11: 10 | B11: =2*SIN(A11*PI()*Dashboard!$C$3)*(COS(A11*PI()*Dashboard!$C$9)-COS(A11*PI()*Dashboard!$C$10))/(A11*PI()) -> 0 | C11: =SUM($B$2:B11) -> 0.36432727 | E11: =2*SIN(A11*PI()*Dashboard!$C$3)*(COS(A11*PI()*Dashboard!$C$11)-COS(A11*PI()*Dashboard!$C$12))/(A11*PI()) -> 0.0037571386 | F11: =SUM($E$2:E11) -> 0.19911418 | H11: =2*SIN(A11*PI()*Dashboard!$C$3)*(COS(A11*PI()*Dashboard!$C$13)-COS(A11*PI()*Dashboard!$C$14))/(A11*PI()) -> -0.0037571386 | I11: =SUM($H$2:H11) -> 0.37363848
A12: 11 | B12: =2*SIN(A12*PI()*Dashboard!$C$3)*(COS(A12*PI()*Dashboard!$C$9)-COS(A12*PI()*Dashboard!$C$10))/(A12*PI()) -> 0.03997058 | C12: =SUM($B$2:B12) -> 0.40429785 | E12: =2*SIN(A12*PI()*Dashboard!$C$3)*(COS(A12*PI()*Dashboard!$C$11)-COS(A12*PI()*Dashboard!$C$12))/(A12*PI()) -> 0.039169908 | F12: =SUM($E$2:E12) -> 0.23828409 | H12: =2*SIN(A12*PI()*Dashboard!$C$3)*(COS(A12*PI()*Dashboard!$C$13)-COS(A12*PI()*Dashboard!$C$14))/(A12*PI()) -> 0.036551446 | I12: =SUM($H$2:H12) -> 0.41018993
A13: 12 | B13: =2*SIN(A13*PI()*Dashboard!$C$3)*(COS(A13*PI()*Dashboard!$C$9)-COS(A13*PI()*Dashboard!$C$10))/(A13*PI()) -> 0.0238671 | C13: =SUM($B$2:B13) -> 0.42816495 | E13: =2*SIN(A13*PI()*Dashboard!$C$3)*(COS(A13*PI()*Dashboard!$C$11)-COS(A13*PI()*Dashboard!$C$12))/(A13*PI()) -> 0.0024156828 | F13: =SUM($E$2:E13) -> 0.24069977 | H13: =2*SIN(A13*PI()*Dashboard!$C$3)*(COS(A13*PI()*Dashboard!$C$13)-COS(A13*PI()*Dashboard!$C$14))/(A13*PI()) -> -0.026282783 | I13: =SUM($H$2:H13) -> 0.38390715
... A501: 500 | B501: =2*SIN(A501*PI()*Dashboard!$C$3)*(COS(A501*PI()*Dashboard!$C$9)-COS(A501*PI()*Dashboard!$C$10))/(A501*PI()) -> 0 | C501: =SUM($B$2:B501) -> -0.019355529 | E501: =2*SIN(A501*PI()*Dashboard!$C$3)*(COS(A501*PI()*Dashboard!$C$11)-COS(A501*PI()*Dashboard!$C$12))/(A501*PI()) -> 0 | F501: =SUM($E$2:E501) -> 1.0402218 | H501: =2*SIN(A501*PI()*Dashboard!$C$3)*(COS(A501*PI()*Dashboard!$C$13)-COS(A501*PI()*Dashboard!$C$14))/(A501*PI()) -> 0 | I501: =SUM($H$2:H501) -> -0.019540432
